Workbook
Name _4Dpro_connectivity: #REF!
Name Accessories: #REF!
Name Accessories_Rittal: #REF!
Name Adapters_and_distributors: #REF!
Name Aeco: #REF!
Name Aeco: #REF!
Name Alarm: #REF!
Name Alarm: #REF!
Name Alarm_Type_Description: #REF!
Name Automation_Software: #REF!
Name Avio: #REF!
Name Avio: #REF!
Name Banner: #REF!
Name Banner: #REF!
Name Banner_Accessories: #REF!
Name Box_PC: #REF!
Name Box_PC: #REF!
Name Cables_and_connectors: #REF!
Name Camera: #REF!
Name Circuits_Breakers: #REF!
Name Climate_Control: #REF!
Name Command_panel_housing_with_door_Stainless_steel: #REF!
Name Commercial_TV_LG: #REF!
Name Compact_enclosures_AE: #REF!
Name Compact_Enclosures_Stainless_Steel: #REF!
Name Computer_Equipment: #REF!
Name CONNECTING_CABLES: #REF!
Name Counters: #REF!
Name Cover_Hinge: #REF!
Name Cover_Retainer: #REF!
Name CSE: #REF!
Name CSE: #REF!
Name Dell: #REF!
Name Dell: #REF!
Name Dell_Tablet: #REF!
Name DIN_Rail: #REF!
Name Display_Hardware: #REF!
Name Downtime_Video_Analysis: #REF!
Name Exertis: #REF!
Name Exertis: #REF!
Name Exertis_Tablet: #REF!
Name Fibre_Optic_Sensors: #REF!
Name GE: #REF!
Name GE: #REF!
Name Gopro: #REF!
Name Gopro: #REF!
Name GTW_S7_1200_TYP001: #REF!
Name Hinges: #REF!
Name HP: #REF!
Name HP: #REF!
Name Hygienic_Design: #REF!
Name Hygienic_Design_Terminal_Boxes: #REF!
Name Image_based_code_readers: #REF!
Name Inductive_Sensors: #REF!
Name Industrial_Ethernet: #REF!
Name Industrial_Monitors_and_Thin_Clients: #REF!
Name Industrial_Monitors_and_Thin_Clients: #REF!
Name Industrial_PC: #REF!
Name Industrial_Wireless_LAN: #REF!
Name Installing_and_testing: #REF!

Sheet Home
Y38: Legend
Z39: Scope review with Customer
Z40: Internal SmartFactory use
A41: Version | B41: Issued by | C41: Date
A42: 5.3 | B42: YB | C42: 45393

Sheet Project Description
A1: Project Overview
A2: 1. Title and general data | B2: General project information
A3: Project Name
A4: Project Code
A5: Company
A6: Site
A7: Date
A8: Target delivery date
A9: Contact person
A10: 2. Where to begin? What problems are you trying to solve? | B10: Identify pain points: What are the specific challenges that negatively impact your organisation's efficiency or costs?
A11: List of Priority Issues to be resolved
A12: a. What manual data do you currently record?
A13: b. Do you use MS Excel for loss analysis?
A14: c. Do you record Scrap, Rework or Rate losses?
A15: d. Do you record changeovers and planned downtimes?
A16: e. Do you record set-up times?
A17: f. Do you record equipment centreline settings?
A18: g. How do you measure and record the quality of your products?
A19: h. What automated data collection tools are already in place?
A20: i. Do you have a paper-based routing system?
A21: j. Have you performed value stream mapping of your process?
A23: 3. Business Value (top 3 objectives) | B23: Define your goals: What do you want to achieve from your digital transformation strategy? (e.g. Reduce operating costs, increase capacity, reduce energy, improve customer satisfaction, etc.)
A27: 4. Change Management | B27: Is you organisation ready to use this data to help drive change?
A28: a. Data readiness: Do you have the necessary data infrastructure and quality to support your digital initiatives?
A29: b. Cultural readiness: Is your organisation open to change and innovation?
A30: c. Skills and talent: Do you have the right skills and talent to execute your strategy?
A31: d. Are the roles and responsibilities in your organisation aligned to support data-driven decision making?
A32: e. How will your organisation interpret and use data on a day-to-day basis, to make informed decisions?

Sheet High Level Project Requirem
B1: High Level Requirements | C1: Value | D1: Samples/notes
B2: Plant Model
B3: Project Name
B4: Project Code
B5: Company name
B6: Site name
B7: Number of Departments/Value Streams
B8: Number of Lines
B9: Number of Cells
B10: Total number of Production Units (PU’s)
B13: Modules Required
B14: Performance Dashboards (OEE, etc.)
B15: Sustainability Dashboards (EnPI’s)
... B31: Production Management
B32: - Product Manager | D32: (include # of SKU’s)
B33: - Specification Manager
B34: - Alerting Manager
B35: - Production Scheduler
B36: Configuration
B37: - User Management
B38: - Support
B39: - Infrastructure monitoring
B40: - SOP’s
B41: - Video SOP’s
B44: Connectivity Requirements
B45: Number of PU’s with PLC’s
B46: Number of these PLC’s which have OPC UA connectivity and are ready for integration
... B59: Infrastructure Requirements
B60: How many environments are required? SmartFactory recommends a min of 2 (TRN, PROD). | D60: (see system spec doc.)
B61: Is the Historian server/VM being supplied by SmartFactory? | D61: (see system spec doc.)
B62: Is Historian server mirroring required? | D62: (see system spec doc.)
B63: Is the Application server/VM being supplied by SmartFactory? | D63: (see system spec doc.)
B64: Is the Application server cloud hosted?
B65: Is the SQL server/VM being supplied by SmartFactory?
B66: Is the SQL server cloud hosted?
B67: Are the MS Windows licenses being supplied by SmartFactory?
B68: Is the SQL License being supplied by SmartFactory?
B69: Is remote monitoring of servers and services required (SmartFactory recommend PRTG)?
B70: Is secure remote access required (SmartFactory recommend OpenVPN)
B71: Is secure remote PLC access required (SmartFactory recommend Siemens Sinema RC)
...

Sheet Business Value & Risks
B1: Business Value, Risks & Objectives | C1: Comments/ Questions | D1: Risk
A3: Risks - Business Value & Objectives | D3: Mark [X]
B4: Problem Clarity: Is the problem that the software platform aims to solve, clearly defined and understood by all stakeholders?
B5: Business Value: Is the business value to be created by the platform clearly articulated and agreed upon?
B6: Scope: Is there an existing URS defined. Has it been shared?
B7: Prior Implementation: Has a similar solution been implemented previously, either within the site or the organisation? If so, what lessons can be learned from these experiences to inform the current project?
B8: Sponsor: Who is sponsoring the project?
B9: Owner: Who is responsible for implementing the solution on site?
B10: Site Audit: Is an audit of the existing equipment/facility required?
A12: Risks - Security & Connectivity
B13: Security: Who is responsible for security and remote access to internal networks?
B14: IT Support: Is IT support local or global? Is it provided by an outside 3rd party?
B15: Network architecture: Is there an OT network in place? Are the IT and OT networks appropriately segregated?
B16: Legacy Equipment: Is there a solution in place to extract data from Legacy Equipment
B17: Manual Assembly Processes: Is there a solution in place to extract data from manual workstations?
B18: Connectivity Readiness: Are the existing PLC’s on-site already prepared for integration with a data collection system?
A19: Risks - Culture & Knowledge
B20: Culture: Will the culture on site be supportive or obstructive of this initiative?
B21: Knowledge: Have the gaps in the technical abilities required for this initiative, been assessed?
B22: Budget: Is a budget available for this initiative?
B23: Decision making authority: Will the decision to proceed with the project be made locally or at a global level?
B24: Schedule: What are the expectations in terms of project implementation?
B25: Road blocks: What could prevent the project from proceeding?
A27: Risk Reducing Actions: What actions are required to mitigate these risks?

Sheet Plant Model
A1: ='Project Description'!A3 -> Project Name | B1: =IF('Project Description'!B3>0, 'Project Description'!B3, " ")
A2: ='Project Description'!A4 -> Project Code | B2: =IF('Project Description'!B4>0, 'Project Description'!B4, " ")
A3: ='Project Description'!A5 -> Company | B3: =IF('Project Description'!B5>0, 'Project Description'!B5, " ")
A6: Site | B6: Value Stream/ Department | C6: Line/Cell Name | D6: Production Unit Name | E6: Downtime Constraint | F6: Product Count Constraint | G6: Step
A13: Total | B13: =SUBTOTAL(109,Plant_Model[Value Stream/ Department]) -> 0 | C13: =SUBTOTAL(109,Plant_Model[Line/Cell Name]) -> 0 | D13: =SUBTOTAL(109,Plant_Model[Production Unit Name]) -> 0 | E13: =SUBTOTAL(109,Plant_Model[Production Unit Name]) -> 0 | F13: =SUBTOTAL(109,Plant_Model[Production Unit Name]) -> 0 | G13: =SUBTOTAL(109,Plant_Model[Production Unit Name]) -> 0

Sheet Field Devices
A1: ='Project Description'!A3 -> Project Name | B1: =IF('Project Description'!B3>0, 'Project Description'!B3, " ")
A2: ='Project Description'!A4 -> Project Code | B2: =IF('Project Description'!B4>0, 'Project Description'!B4, " ")
A3: ='Project Description'!A5 -> Company | B3: =IF('Project Description'!B5>0, 'Project Description'!B5, " ")
A6: Site | B6: Value Stream | C6: Process | D6: PU | E6: Proposal | F6: PLC Number | G6: PLC Brand/Model | H6: TL70 Counter/Call For Help | I6: Call for Help (Button + Light) | J6: Set Up Switch (Button+Light) | K6: Photooptic Sensor | L6: Current Sensor | M6: Current Sensor 0.5 mA | N6: Festo Pressure switch | O6: Wireless Pendant | P6: Comments
A7: ='Plant Model'!A7 -> 0 | B7: ='Plant Model'!B7 -> 0 | C7: ='Plant Model'!C7 -> 0 | D7: ='Plant Model'!D7 -> 0 | H7: 2 | I7: 2 | K7: 1 | O7: 2
A8: ='Plant Model'!A8 -> 0 | B8: ='Plant Model'!B8 -> 0 | C8: ='Plant Model'!C8 -> 0 | D8: ='Plant Model'!D8 -> 0
A9: ='Plant Model'!A9 -> 0 | B9: ='Plant Model'!B9 -> 0 | C9: ='Plant Model'!C9 -> 0 | D9: ='Plant Model'!D9 -> 0
A10: ='Plant Model'!A10 -> 0 | B10: ='Plant Model'!B10 -> 0 | C10: ='Plant Model'!C10 -> 0 | D10: ='Plant Model'!D10 -> 0
A11: ='Plant Model'!A11 -> 0 | B11: ='Plant Model'!B11 -> 0 | C11: ='Plant Model'!C11 -> 0 | D11: ='Plant Model'!D11 -> 0
A12: ='Plant Model'!A12 -> 0 | B12: ='Plant Model'!B12 -> 0 | C12: ='Plant Model'!C12 -> 0 | D12: ='Plant Model'!D12 -> 0
A13: Total | F13: =SUBTOTAL(109,Scope[PLC Number]) -> 0 | H13: =SUBTOTAL(109,Scope[TL70 Counter/Call For Help]) -> 2 | I13: =SUBTOTAL(109,Scope[Call for Help (Button + Light)]) -> 2 | J13: =SUBTOTAL(109,Scope[Set Up Switch (Button+Light)]) -> 0 | K13: =SUBTOTAL(109,Scope[Photooptic Sensor]) -> 1 | L13: =SUBTOTAL(109,Scope[Current Sensor]) -> 0 | M13: =SUBTOTAL(109,Scope[Current Sensor 0.5 mA]) -> 0 | N13: =SUBTOTAL(109,Scope[Festo Pressure switch]) -> 0 | O13: =SUBTOTAL(109,Scope[Wireless Pendant]) -> 2

Sheet Tags
A1: ='Project Description'!A3 -> Project Name | B1: =IF('Project Description'!B3>0, 'Project Description'!B3, " ")
A2: ='Project Description'!A4 -> Project Code | B2: =IF('Project Description'!B4>0, 'Project Description'!B4, " ")
A3: ='Project Description'!A5 -> Company | B3: =IF('Project Description'!B5>0, 'Project Description'!B5, " ")
A6: Site | B6: Value Stream | C6: Process | D6: PU | E6: Tags | F6: Comments
A7: ='Plant Model'!A7 -> 0 | B7: ='Plant Model'!B7 -> 0 | C7: ='Plant Model'!C7 -> 0 | D7: ='Plant Model'!D7 -> 0
A8: ='Plant Model'!A8 -> 0 | B8: ='Plant Model'!B8 -> 0 | C8: ='Plant Model'!C8 -> 0 | D8: ='Plant Model'!D8 -> 0
A9: ='Plant Model'!A9 -> 0 | B9: ='Plant Model'!B9 -> 0 | C9: ='Plant Model'!C9 -> 0 | D9: ='Plant Model'!D9 -> 0
A10: ='Plant Model'!A10 -> 0 | B10: ='Plant Model'!B10 -> 0 | C10: ='Plant Model'!C10 -> 0 | D10: ='Plant Model'!D10 -> 0
A11: ='Plant Model'!A11 -> 0 | B11: ='Plant Model'!B11 -> 0 | C11: ='Plant Model'!C11 -> 0 | D11: ='Plant Model'!D11 -> 0
A12: Total | E12: =SUBTOTAL(109,Data_Sources[Tags]) -> 0 | F12: =SUBTOTAL(109,Data_Sources[Comments]) -> 0
A16: PU | B16: Equipment | C16: Tag
A17: ='Plant Model'!$D$7 -> 0 | B17: PLC | C17: Heartbeat
A18: ='Plant Model'!$D$7 -> 0 | B18: PLC | C18: State
A19: ='Plant Model'!$D$7 -> 0 | B19: PLC | C19: ProductionCountGood
A20: ='Plant Model'!$D$7 -> 0 | B20: PLC | C20: ProductionCountScrap
A21: ='Plant Model'!$D$7 -> 0 | B21: PLC | C21: ScrapCode
A22: ='Plant Model'!$D$7 -> 0 | B22: PLC | C22: StopCode

Sheet Dashboards
A1: ='Project Description'!A3 -> Project Name | B1: =IF('Project Description'!B3>0, 'Project Description'!B3, " ")
A2: ='Project Description'!A4 -> Project Code | B2: =IF('Project Description'!B4>0, 'Project Description'!B4, " ")
A3: ='Project Description'!A5 -> Company | B3: =IF('Project Description'!B5>0, 'Project Description'!B5, " ")
A6: Site | B6: Site View | C6: Energy Consumption | D6: Utility Consumption | E6: Work Order Manager | F6: Condition Monitoring | G6: Reporting (Power BI) | H6: Map Site View | I6: Product Manager | J6: Scheduler | K6: Shift Report
A7: ='Plant Model'!A7 -> 0 | B7: 0 | C7: 0 | D7: 0 | E7: 0 | F7: 0 | G7: 0 | H7: 0 | I7: 0 | J7: 0 | K7: 0
A8: Total | B8: =SUBTOTAL(109,Visualization[Site View]) -> 0 | C8: =SUBTOTAL(109,Visualization[Energy Consumption]) -> 0 | D8: =SUBTOTAL(109,Visualization[Utility Consumption]) -> 0 | E8: =SUBTOTAL(109,Visualization[Work Order Manager]) -> 0 | F8: =SUBTOTAL(109,Visualization[Condition Monitoring]) -> 0 | G8: =SUBTOTAL(109,Visualization[Reporting (Power BI)]) -> 0 | H8: =SUBTOTAL(109,Visualization[Map Site View]) -> 0 | I8: =SUBTOTAL(109,Visualization[Product Manager]) -> 0 | J8: =SUBTOTAL(109,Visualization[Scheduler]) -> 0 | K8: =SUBTOTAL(109,Visualization[Shift Report]) -> 0
A10: Site | B10: Value Stream/ Department | C10: Line/Cell Name | D10: Cell View | E10: Line View | F10: Grid View | G10: Call for Help | H10: Call for Parts | I10: Energy Consumption | J10: Utility Consumption | K10: Process Verification | L10: Condition Monitoring | M10: Shift Report
A11: ='Plant Model'!A7 -> 0 | B11: ='Plant Model'!B7 -> 0 | C11: ='Plant Model'!C7 -> 0 | D11: 0 | E11: 0 | F11: 0 | G11: 0 | H11: 0 | I11: 0 | J11: 0 | K11: 0 | L11: 0 | M11: 0
A12: ='Plant Model'!A8 -> 0 | B12: ='Plant Model'!B8 -> 0 | C12: ='Plant Model'!C8 -> 0
A13: ='Plant Model'!A9 -> 0 | B13: ='Plant Model'!B9 -> 0 | C13: ='Plant Model'!C9 -> 0
A14: ='Plant Model'!A10 -> 0 | B14: ='Plant Model'!B10 -> 0 | C14: ='Plant Model'!C10 -> 0
A15: ='Plant Model'!A11 -> 0 | B15: ='Plant Model'!B11 -> 0 | C15: ='Plant Model'!C11 -> 0
A16: Total | D16: =SUBTOTAL(109,Table14[Cell View]) -> 0 | E16: =SUBTOTAL(109,Table14[Line View]) -> 0 | F16: =SUBTOTAL(109,Table14[Grid View]) -> 0 | G16: =SUBTOTAL(109,Table14[Call for Help]) -> 0 | H16: =SUBTOTAL(109,Table14[Call for Parts]) -> 0 | I16: =SUBTOTAL(109,Table14[Energy Consumption]) -> 0 | J16: =SUBTOTAL(109,Table14[Utility Consumption]) -> 0 | K16: =SUBTOTAL(109,Table14[Process Verification]) -> 0 | L16: =SUBTOTAL(109,Table14[Condition Monitoring]) -> 0 | M16: =SUBTOTAL(109,Table14[Shift Report]) -> 0
A18: Site | B18: Value Stream/ Department | C18: Line/Cell Name | D18: Production Unit Name | E18: Downtime Viewer (DTVR) | F18: Manual Data Entry System (MDES) | G18: Call for Help | H18: Call for Parts | I18: Energy Consumption | J18: Utility Consumption | K18: Process Verification | L18: Condition Monitoring | M18: Pick to Light
A19: ='Plant Model'!A7 -> 0 | B19: ='Plant Model'!B7 -> 0 | C19: ='Plant Model'!C7 -> 0 | D19: ='Plant Model'!D7 -> 0 | E19: 0 | F19: 0 | G19: 0 | H19: 0 | I19: 0 | J19: 0 | K19: 0 | L19: 0 | M19: 0
A20: ='Plant Model'!A8 -> 0 | B20: ='Plant Model'!B8 -> 0 | C20: ='Plant Model'!C8 -> 0 | D20: ='Plant Model'!D8 -> 0
A21: ='Plant Model'!A9 -> 0 | B21: ='Plant Model'!B9 -> 0 | C21: ='Plant Model'!C9 -> 0 | D21: ='Plant Model'!D9 -> 0
A22: ='Plant Model'!A10 -> 0 | B22: ='Plant Model'!B10 -> 0 | C22: ='Plant Model'!C10 -> 0 | D22: ='Plant Model'!D10 -> 0
A23: ='Plant Model'!A11 -> 0 | B23: ='Plant Model'!B11 -> 0 | C23: ='Plant Model'!C11 -> 0 | D23: ='Plant Model'!D11 -> 0
A24: ='Plant Model'!A12 -> 0 | B24: ='Plant Model'!B12 -> 0 | C24: ='Plant Model'!C12 -> 0 | D24: ='Plant Model'!D12 -> 0
A25: Total | E25: =SUBTOTAL(109,Table15[Downtime Viewer (DTVR)]) -> 0 | F25: =SUBTOTAL(109,Table15[Manual Data Entry System (MDES)]) -> 0 | G25: =SUBTOTAL(109,Table15[Call for Help]) -> 0 | H25: =SUBTOTAL(109,Table15[Call for Parts]) -> 0 | I25: =SUBTOTAL(109,Table15[Energy Consumption]) -> 0 | J25: =SUBTOTAL(109,Table15[Utility Consumption]) -> 0 | K25: =SUBTOTAL(109,Table15[Process Verification]) -> 0 | L25: =SUBTOTAL(109,Table15[Condition Monitoring]) -> 0 | M25: =SUBTOTAL(109,Table15[Pick to Light]) -> 0
